<?xml version="1.0"?>
<robot name="cr5_robot"
    xmlns:xacro="http://ros.org/wiki/xacro">

    <xacro:arg name="use_sim" default="true" />
    <xacro:arg name="robot_ip" default="192.168.0.154" />

    <xacro:include filename="inertia_macros.xacro" />

    <link name="dummy_link" />
    <link name="base_link">
        <visual>
            <origin xyz="0 0 0" rpy="0 0 0" />
            <geometry>
                <mesh filename="package://cr5_description/meshes/base_link.dae" />
            </geometry>
            <material name="">
                <color rgba="0 0 0 1" />
            </material>
        </visual>
        <collision>
            <origin xyz="0 0 0" rpy="0 0 0" />
            <geometry>
                <mesh filename="package://cr5_description/meshes/base_link.dae" />
            </geometry>
        </collision>
        <xacro:cylinder_inertia m="1.6123" r="0.06" h="0.12" xyz="-8.7268E-07 -0.0032576 -0.0076748"
            rpy="0 0 0" />
    </link>
    <link name="world" />
    <joint name="world_joint" type="fixed">
        <origin xyz="0 0 0.03" rpy="0 0 0" />
        <parent link="world" />
        <child link="dummy_link" />
    </joint>

    <joint name="dummy_joint" type="fixed">
        <parent link="dummy_link" />
        <child link="base_link" />
    </joint>


    <link name="Link1">
        <visual>
            <origin xyz="0 0 0" rpy="0 0 0" />
            <geometry>
                <mesh filename="package://cr5_description/meshes/Link1.dae" />
            </geometry>
            <material name="">
                <color rgba="1 1 1 1" />
            </material>
        </visual>
        <collision>
            <origin xyz="0 0 0" rpy="0 0 0" />
            <geometry>
                <mesh filename="package://cr5_description/meshes/Link1.dae" />
            </geometry>
        </collision>
        <xacro:cylinder_inertia m="1.6123" r="0.06" h="0.12" xyz="-8.7268E-07 -0.0032576 -0.0076748"
            rpy="0 0 0" />
    </link>

    <joint name="joint1" type="revolute">
        <origin xyz="0 0 0.147" rpy="0 0 0" />
        <parent link="base_link" />
        <child link="Link1" />
        <axis xyz="0 0 1" />
        <limit lower="-6.27" upper="6.27" effort="300" velocity="100" />
    </joint>

    <link name="Link2">
        <visual>
            <origin xyz="0 0 0" rpy="0 0 0" />
            <geometry>
                <mesh filename="package://cr5_description/meshes/Link2.dae" />
            </geometry>
            <material name="">
                <color rgba="1 1 1 1" />
            </material>
        </visual>
        <collision>
            <origin xyz="0 0 0" rpy="0 0 0" />
            <geometry>
                <mesh filename="package://cr5_description/meshes/Link2.dae" />
            </geometry>
        </collision>
        <xacro:cylinder_inertia m="1.6123" r="0.06" h="0.12" xyz="-0.21351 -1.3842E-06 0.14252"
            rpy="0 0 0" />
    </link>

    <joint name="joint2" type="revolute">
        <origin xyz="0 0 0" rpy="1.5708 1.5708 0" />
        <parent link="Link1" />
        <child link="Link2" />
        <axis xyz="0 0 1" />
        <limit lower="-6.27" upper="6.27" effort="300" velocity="100" />
    </joint>

    <link name="Link3">
        <visual>
            <origin xyz="0 0 0" rpy="0 0 0" />
            <geometry>
                <mesh filename="package://cr5_description/meshes/Link3.dae" />
            </geometry>
            <material name="">
                <color rgba="1 1 1 1" />
            </material>
        </visual>
        <collision>
            <origin xyz="0 0 0" rpy="0 0 0" />
            <geometry>
                <mesh filename="package://cr5_description/meshes/Link3.dae" />
            </geometry>
        </collision>
        <xacro:cylinder_inertia m="1.6123" r="0.06" h="0.12" xyz="-0.15231 -1.4079E-07 0.022693"
            rpy="0 0 0" />
    </link>

    <joint name="joint3" type="revolute">
        <origin xyz="-0.427 0 0" rpy="0 0 0" />
        <parent link="Link2" />
        <child link="Link3" />
        <axis xyz="0 0 1" />
        <limit lower="-2.86" upper="2.86" effort="300" velocity="100" />
    </joint>

    <link name="Link4">
        <visual>
            <origin xyz="0 0 0" rpy="0 0 0" />
            <geometry>
                <mesh filename="package://cr5_description/meshes/Link4.dae" />
            </geometry>
            <material name="">
                <color rgba="1 1 1 1" />
            </material>
        </visual>
        <collision>
            <origin xyz="0 0 0" rpy="0 0 0" />
            <geometry>
                <mesh filename="package://cr5_description/meshes/Link4.dae" />
            </geometry>
        </collision>
        <xacro:cylinder_inertia m="1.6123" r="0.06" h="0.12" xyz="-3.2386E-07 -0.002077 -0.0015548"
            rpy="0 0 0" />
    </link>

    <joint name="joint4" type="revolute">
        <origin xyz="-0.357 0 0.141" rpy="0 0 -1.5708" />
        <parent link="Link3" />
        <child link="Link4" />
        <axis xyz="0 0 1" />
        <limit lower="-6.27" upper="6.27" effort="300" velocity="100" />
    </joint>
    <link name="Link5">
        <visual>
            <origin xyz="0 0 0" rpy="0 0 0" />
            <geometry>
                <mesh filename="package://cr5_description/meshes/Link5.dae" />
            </geometry>
            <material name="">
                <color rgba="1 1 1 1" />
            </material>
        </visual>
        <collision>
            <origin xyz="0 0 0" rpy="0 0 0" />
            <geometry>
                <mesh filename="package://cr5_description/meshes/Link5.dae" />
            </geometry>
        </collision>
        <xacro:cylinder_inertia m="1.6123" r="0.06" h="0.12" xyz="-3.7738E-07 -0.0045777 -0.0012971"
            rpy="0 0 0" />
    </link>

    <joint name="joint5" type="revolute">
        <origin xyz="0 -0.116 0" rpy="1.5708 0 0" />
        <parent link="Link4" />
        <child link="Link5" />
        <axis xyz="0 0 1" />
        <limit lower="-6.27" upper="6.27" effort="300" velocity="100" />
    </joint>

    <link name="Link6">
        <visual>
            <origin xyz="0 0 0" rpy="0 0 0" />
            <geometry>
                <mesh filename="package://cr5_description/meshes/Link6.dae" />
            </geometry>
            <material name="">
                <color rgba="1 1 1 1" />
            </material>
        </visual>
        <collision>
            <origin xyz="0 0 0" rpy="0 0 0" />
            <geometry>
                <mesh filename="package://cr5_description/meshes/Link6.dae" />
            </geometry>
        </collision>
        <xacro:cylinder_inertia m="1.6123" r="0.06" h="0.12" xyz="5.0777E-11 9.3774E-05 -0.019285"
            rpy="0 0 0" />
    </link>

    <joint name="joint6" type="revolute">
        <origin xyz="0 0.105 0" rpy="-1.5708 0 0" />
        <parent link="Link5" />
        <child link="Link6" />
        <axis xyz="0 0 1" />
        <limit lower="-6.27" upper="6.27" effort="300" velocity="100" />
    </joint>


    <link name="tool0" />

    <joint name="joint_tool0" type="fixed">
        <origin xyz="0 0 0.065" rpy="0 0 0" />
        <parent link="Link6" />
        <child link="tool0" />
    </joint>

</robot>